
#######################################################################
# +-----------------------------------------------------------------+ #
# |                            BO3 object                           | #
# +-----------------------------------------------------------------+ #
#######################################################################

Author: planet_houki

Description: No description given

Version: 3

SettingsMode: WriteWithoutComments


#######################################################################
# +-----------------------------------------------------------------+ #
# |                          Main settings                          | #
# +-----------------------------------------------------------------+ #
#######################################################################

Tree: false

Frequency: 1

Rarity: 1.0

RotateRandomly: false

SpawnHeight: highestBlock

SpawnHeightOffset: 30

SpawnHeightVariance: 10

##############################
# Height Limits for the BO3. #
##############################

MinHeight: 0

MaxHeight: 256

######################
# Extrusion settings #
######################

ExtrudeMode: None

ExtrudeThroughBlocks: AIR

MaxBranchDepth: 10

ExcludedBiomes: All


#######################################################################
# +-----------------------------------------------------------------+ #
# |                      Source block settings                      | #
# +-----------------------------------------------------------------+ #
#######################################################################

SourceBlocks: AIR

MaxPercentageOutsideSourceBlock: 100

OutsideSourceBlock: placeAnyway

IsOTGPlus: false

InheritBO3: 

InheritBO3Rotation: NORTH

OverrideChildSettings: true

OverrideParentHeight: false

CanOverride: false

BranchFrequency: 0

BranchFrequencyGroup: 

MustBeBelowOther: false

MustBeInside: 

CannotBeInside: 

ReplacesBO3: 

CanSpawnOnWater: true

SpawnOnWaterOnly: false

SpawnUnderWater: false

SpawnAtWaterLevel: false

HeightOffset: 0

RemoveAir: true

ReplaceAbove: 

ReplaceBelow: 

ReplaceWithBiomeBlocks: true

ReplaceWithGroundBlock: DIRT

ReplaceWithSurfaceBlock: GRASS

SmoothRadius: 0

SmoothHeightOffset: 0

SmoothStartTop: false

SmoothStartWood: false

SmoothingSurfaceBlock: 

SmoothingGroundBlock: 

BO3Group: 

IsSpawnPoint: false


#######################################################################
# +-----------------------------------------------------------------+ #
# |                              Blocks                             | #
# +-----------------------------------------------------------------+ #
#######################################################################

RandomBlock(0,4,-7,CHEST:3,endship2/chest_01.nbt,50,CHEST:3,endship2/chest_02.nbt,50,CHEST:3,endship2/chest_03.nbt,50,CHEST:3,endship2/chest_04.nbt,50,CHEST:3,endship2/chest_01.nbt,100)
Block(0,8,-14,SKULL,endship2/skull_north.nbt)
Block(0,7,11,BREWING_STAND:5,endship2/brewing_stand_01.nbt)
Block(-6,9,5,PURPUR_STAIRS:4)
Block(-6,9,6,PURPUR_STAIRS:4)
Block(-6,9,7,PURPUR_STAIRS:0)
Block(-6,9,8,PURPUR_STAIRS:0)
Block(-6,9,9,PURPUR_STAIRS:4)
Block(-6,9,10,PURPUR_STAIRS:4)
Block(-6,9,11,PURPUR_STAIRS:0)
Block(-6,9,12,PURPUR_STAIRS:0)
Block(-6,9,13,PURPUR_STAIRS:4)
Block(-6,9,14,PURPUR_STAIRS:7)
Block(-5,5,-1,PURPUR_STAIRS:4)
Block(-5,5,2,PURPUR_STAIRS:4)
Block(-5,5,6,PURPUR_STAIRS:6)
Block(-5,5,7,PURPUR_STAIRS:4)
Block(-5,5,8,PURPUR_STAIRS:0)
Block(-5,5,9,PURPUR_STAIRS:4)
Block(-5,5,10,PURPUR_STAIRS:4)
Block(-5,5,11,PURPUR_STAIRS:0)
Block(-5,5,12,PURPUR_STAIRS:4)
Block(-5,5,13,PURPUR_STAIRS:4)
Block(-5,6,13,END_ROD)
Block(-5,9,5,PURPUR_STAIRS:6)
Block(-5,9,6,PURPUR_BLOCK)
Block(-5,9,7,PURPUR_BLOCK)
Block(-5,9,8,PURPUR_BLOCK)
Block(-5,9,9,PURPUR_BLOCK)
Block(-5,9,10,PURPUR_BLOCK)
Block(-5,9,11,PURPUR_BLOCK)
Block(-5,9,12,PURPUR_BLOCK)
Block(-5,9,13,PURPUR_BLOCK)
Block(-5,9,14,PURPUR_STAIRS:7)
Block(-5,10,6,PURPUR_BLOCK)
Block(-5,10,7,PURPUR_STAIRS:0)
Block(-5,10,8,PURPUR_STAIRS:0)
Block(-5,10,9,PURPUR_STAIRS:0)
Block(-5,10,10,PURPUR_STAIRS:0)
Block(-5,10,11,PURPUR_STAIRS:0)
Block(-5,10,12,PURPUR_STAIRS:0)
Block(-5,10,13,PURPUR_BLOCK)
Block(-4,3,-1,PURPUR_STAIRS:4)
Block(-4,3,3,PURPUR_STAIRS:4)
Block(-4,3,7,PURPUR_STAIRS:4)
Block(-4,3,11,PURPUR_STAIRS:4)
Block(-4,4,-3,PURPUR_BLOCK)
Block(-4,4,-2,PURPUR_BLOCK)
Block(-4,4,-1,PURPUR_BLOCK)
Block(-4,4,0,PURPUR_BLOCK)
Block(-4,4,1,PURPUR_BLOCK)
Block(-4,4,2,PURPUR_BLOCK)
Block(-4,4,3,PURPUR_BLOCK)
Block(-4,4,4,PURPUR_BLOCK)
Block(-4,4,5,PURPUR_BLOCK)
Block(-4,4,6,PURPUR_BLOCK)
Block(-4,4,7,PURPUR_BLOCK)
Block(-4,4,8,PURPUR_BLOCK)
Block(-4,4,9,PURPUR_BLOCK)
Block(-4,4,10,PURPUR_BLOCK)
Block(-4,4,11,PURPUR_BLOCK)
Block(-4,4,12,PURPUR_STAIRS:7)
Block(-4,5,-3,PURPUR_BLOCK)
Block(-4,5,-2,PURPUR_BLOCK)
Block(-4,5,-1,PURPUR_BLOCK)
Block(-4,5,0,PURPUR_BLOCK)
Block(-4,5,1,PURPUR_BLOCK)
Block(-4,5,2,PURPUR_BLOCK)
Block(-4,5,3,PURPUR_BLOCK)
Block(-4,5,4,PURPUR_BLOCK)
Block(-4,5,5,PURPUR_BLOCK)
Block(-4,5,6,PURPUR_BLOCK)
Block(-4,5,7,PURPUR_BLOCK)
Block(-4,5,8,PURPUR_BLOCK)
Block(-4,5,9,PURPUR_BLOCK)
Block(-4,5,10,PURPUR_BLOCK)
Block(-4,5,11,PURPUR_BLOCK)
Block(-4,5,12,PURPUR_BLOCK)
Block(-4,5,13,PURPUR_STAIRS:7)
Block(-4,6,-3,PURPUR_BLOCK)
Block(-4,6,-2,PURPUR_BLOCK)
Block(-4,6,0,PURPUR_BLOCK)
Block(-4,6,1,PURPUR_BLOCK)
Block(-4,6,3,PURPUR_BLOCK)
Block(-4,6,4,PURPUR_BLOCK)
Block(-4,6,5,PURPUR_BLOCK)
Block(-4,6,6,PURPUR_BLOCK)
Block(-4,6,7,PURPUR_PILLAR:0)
Block(-4,6,8,END_BRICKS)
Block(-4,6,9,END_BRICKS)
Block(-4,6,10,END_BRICKS)
Block(-4,6,11,END_BRICKS)
Block(-4,6,12,PURPUR_PILLAR:0)
Block(-4,7,-4,PURPUR_BLOCK)
Block(-4,7,-3,PURPUR_BLOCK)
Block(-4,7,-2,PURPUR_BLOCK)
Block(-4,7,-1,PURPUR_BLOCK)
Block(-4,7,0,PURPUR_BLOCK)
Block(-4,7,1,PURPUR_BLOCK)
Block(-4,7,2,PURPUR_BLOCK)
Block(-4,7,3,PURPUR_BLOCK)
Block(-4,7,4,PURPUR_BLOCK)
Block(-4,7,5,PURPUR_BLOCK)
Block(-4,7,6,PURPUR_BLOCK)
Block(-4,7,7,PURPUR_PILLAR:0)
Block(-4,7,8,END_BRICKS)
Block(-4,7,9,STAINED_GLASS:2)
Block(-4,7,10,STAINED_GLASS:2)
Block(-4,7,11,END_BRICKS)
Block(-4,7,12,PURPUR_PILLAR:0)
Block(-4,8,-4,PURPUR_BLOCK)
Block(-4,8,-3,PURPUR_STAIRS:0)
Block(-4,8,-2,PURPUR_STAIRS:0)
Block(-4,8,-1,PURPUR_BLOCK)
Block(-4,8,0,PURPUR_STAIRS:0)
Block(-4,8,1,PURPUR_STAIRS:0)
Block(-4,8,2,PURPUR_BLOCK)
Block(-4,8,3,PURPUR_STAIRS:0)
Block(-4,8,4,PURPUR_STAIRS:0)
Block(-4,8,5,PURPUR_BLOCK)
Block(-4,8,6,PURPUR_BLOCK)
Block(-4,8,7,PURPUR_PILLAR:0)
Block(-4,8,8,END_BRICKS)
Block(-4,8,9,END_BRICKS)
Block(-4,8,10,END_BRICKS)
Block(-4,8,11,END_BRICKS)
Block(-4,8,12,PURPUR_PILLAR:0)
Block(-4,9,-4,END_ROD)
Block(-4,9,5,PURPUR_STAIRS:6)
Block(-4,9,6,PURPUR_BLOCK)
Block(-4,9,7,PURPUR_BLOCK)
Block(-4,9,8,PURPUR_BLOCK)
Block(-4,9,9,PURPUR_BLOCK)
Block(-4,9,10,PURPUR_BLOCK)
Block(-4,9,11,PURPUR_BLOCK)
Block(-4,9,12,PURPUR_BLOCK)
Block(-4,9,13,PURPUR_BLOCK)
Block(-4,9,14,PURPUR_STAIRS)
Block(-4,10,6,PURPUR_STAIRS:2)
Block(-4,10,13,PURPUR_STAIRS)
Block(-3,2,-1,PURPUR_STAIRS:4)
Block(-3,2,3,PURPUR_STAIRS:4)
Block(-3,2,7,PURPUR_STAIRS:4)
Block(-3,2,11,PURPUR_STAIRS:4)
Block(-3,3,-4,PURPUR_BLOCK)
Block(-3,3,-3,PURPUR_BLOCK)
Block(-3,3,-2,PURPUR_BLOCK)
Block(-3,3,-1,PURPUR_BLOCK)
Block(-3,3,0,PURPUR_BLOCK)
Block(-3,3,1,PURPUR_BLOCK)
Block(-3,3,2,PURPUR_BLOCK)
Block(-3,3,3,PURPUR_BLOCK)
Block(-3,3,4,PURPUR_BLOCK)
Block(-3,3,5,PURPUR_BLOCK)
Block(-3,3,6,PURPUR_BLOCK)
Block(-3,3,7,PURPUR_BLOCK)
Block(-3,3,8,PURPUR_BLOCK)
Block(-3,3,9,PURPUR_BLOCK)
Block(-3,3,10,PURPUR_BLOCK)
Block(-3,3,11,PURPUR_BLOCK)
Block(-3,4,-5,PURPUR_BLOCK)
Block(-3,4,-4,PURPUR_BLOCK)
Block(-3,4,11,PURPUR_BLOCK)
Block(-3,5,-5,PURPUR_BLOCK)
Block(-3,5,-4,PURPUR_BLOCK)
Block(-3,5,6,PURPUR_BLOCK)
Block(-3,5,7,PURPUR_BLOCK)
Block(-3,5,8,PURPUR_BLOCK)
Block(-3,5,9,PURPUR_BLOCK)
Block(-3,5,10,PURPUR_BLOCK)
Block(-3,5,11,PURPUR_BLOCK)
Block(-3,5,12,PURPUR_BLOCK)
Block(-3,5,13,PURPUR_STAIRS)
Block(-3,6,-5,PURPUR_BLOCK)
Block(-3,6,-4,PURPUR_BLOCK)
Block(-3,6,5,PURPUR_BLOCK)
Block(-3,6,6,PURPUR_BLOCK)
Block(-3,6,7,PURPUR_BLOCK)
Block(-3,6,12,END_BRICKS)
Block(-3,7,-6,PURPUR_BLOCK)
Block(-3,7,-5,PURPUR_BLOCK)
Block(-3,7,-4,PURPUR_BLOCK)
Block(-3,7,-3,PURPUR_BLOCK)
Block(-3,7,-2,PURPUR_BLOCK)
Block(-3,7,-1,PURPUR_BLOCK)
Block(-3,7,0,PURPUR_BLOCK)
Block(-3,7,1,PURPUR_BLOCK)
Block(-3,7,2,PURPUR_BLOCK)
Block(-3,7,3,PURPUR_BLOCK)
Block(-3,7,4,PURPUR_BLOCK)
Block(-3,7,5,PURPUR_BLOCK)
Block(-3,7,6,PURPUR_BLOCK)
Block(-3,7,7,PURPUR_BLOCK)
Block(-3,7,12,END_BRICKS)
Block(-3,8,-6,PURPUR_BLOCK)
Block(-3,8,-5,PURPUR_STAIRS:0)
Block(-3,8,-4,PURPUR_STAIRS:2)
Block(-3,8,7,PURPUR_BLOCK)
Block(-3,8,12,END_BRICKS)
Block(-3,9,5,PURPUR_STAIRS:6)
Block(-3,9,6,PURPUR_BLOCK)
Block(-3,9,7,PURPUR_BLOCK)
Block(-3,9,8,PURPUR_BLOCK)
Block(-3,9,9,PURPUR_BLOCK)
Block(-3,9,10,PURPUR_BLOCK)
Block(-3,9,11,PURPUR_BLOCK)
Block(-3,9,12,PURPUR_BLOCK)
Block(-3,9,13,PURPUR_BLOCK)
Block(-3,9,14,PURPUR_STAIRS)
Block(-3,10,6,PURPUR_BLOCK)
Block(-3,10,7,PURPUR_STAIRS:1)
Block(-3,10,13,PURPUR_STAIRS)
Block(-2,1,-1,PURPUR_STAIRS:4)
Block(-2,1,3,PURPUR_STAIRS:4)
Block(-2,1,7,PURPUR_STAIRS:4)
Block(-2,2,-4,PURPUR_BLOCK)
Block(-2,2,-3,PURPUR_BLOCK)
Block(-2,2,-2,PURPUR_BLOCK)
Block(-2,2,-1,PURPUR_BLOCK)
Block(-2,2,0,PURPUR_BLOCK)
Block(-2,2,1,PURPUR_BLOCK)
Block(-2,2,2,PURPUR_BLOCK)
Block(-2,2,3,PURPUR_BLOCK)
Block(-2,2,4,PURPUR_BLOCK)
Block(-2,2,5,PURPUR_BLOCK)
Block(-2,2,6,PURPUR_BLOCK)
Block(-2,2,7,PURPUR_BLOCK)
Block(-2,2,8,PURPUR_BLOCK)
Block(-2,2,9,PURPUR_BLOCK)
Block(-2,2,10,PURPUR_BLOCK)
Block(-2,2,11,PURPUR_BLOCK)
Block(-2,3,-6,PURPUR_BLOCK)
Block(-2,3,-5,PURPUR_BLOCK)
Block(-2,3,11,PURPUR_BLOCK)
Block(-2,4,-7,PURPUR_BLOCK)
Block(-2,4,-6,PURPUR_BLOCK)
Block(-2,4,11,PURPUR_BLOCK)
Block(-2,5,-7,PURPUR_BLOCK)
Block(-2,5,-6,PURPUR_BLOCK)
Block(-2,5,6,PURPUR_BLOCK)
Block(-2,5,7,PURPUR_BLOCK)
Block(-2,5,8,PURPUR_BLOCK)
Block(-2,5,9,PURPUR_BLOCK)
Block(-2,5,10,PURPUR_BLOCK)
Block(-2,5,11,PURPUR_BLOCK)
Block(-2,5,12,PURPUR_BLOCK)
Block(-2,5,13,PURPUR_STAIRS:7)
Block(-2,6,-7,PURPUR_BLOCK)
Block(-2,6,-6,PURPUR_BLOCK)
Block(-2,6,5,PURPUR_BLOCK)
Block(-2,6,6,PURPUR_STAIRS)
Block(-2,6,12,END_BRICKS)
Block(-2,7,-8,PURPUR_BLOCK)
Block(-2,7,-7,PURPUR_BLOCK)
Block(-2,7,-6,PURPUR_BLOCK)
Block(-2,7,-5,PURPUR_BLOCK)
Block(-2,7,-4,PURPUR_BLOCK)
Block(-2,7,-3,PURPUR_BLOCK)
Block(-2,7,-2,PURPUR_BLOCK)
Block(-2,7,-1,PURPUR_BLOCK)
Block(-2,7,0,PURPUR_BLOCK)
Block(-2,7,1,PURPUR_BLOCK)
Block(-2,7,2,PURPUR_BLOCK)
Block(-2,7,3,PURPUR_BLOCK)
Block(-2,7,4,PURPUR_BLOCK)
Block(-2,7,5,PURPUR_STAIRS)
Block(-2,7,12,STAINED_GLASS:2)
Block(-2,8,-8,PURPUR_BLOCK)
Block(-2,8,-7,PURPUR_STAIRS:0)
Block(-2,8,-6,PURPUR_STAIRS:2)
Block(-2,8,12,END_BRICKS)
Block(-2,9,7,PURPUR_BLOCK)
Block(-2,9,8,PURPUR_BLOCK)
Block(-2,9,9,PURPUR_BLOCK)
Block(-2,9,10,PURPUR_BLOCK)
Block(-2,9,11,PURPUR_BLOCK)
Block(-2,9,12,PURPUR_BLOCK)
Block(-2,9,13,PURPUR_BLOCK)
Block(-2,9,14,PURPUR_STAIRS:7)
Block(-2,10,7,PURPUR_STAIRS:2)
Block(-2,10,8,PURPUR_PILLAR:0)
Block(-2,10,12,PURPUR_STAIRS:0)
Block(-2,10,13,PURPUR_BLOCK)
Block(-2,21,-2,PURPUR_STAIRS:6)
Block(-2,21,-1,PURPUR_STAIRS:4)
Block(-2,21,0,PURPUR_STAIRS:4)
Block(-2,21,1,PURPUR_STAIRS:4)
Block(-2,21,2,PURPUR_STAIRS:4)
Block(-1,1,-2,PURPUR_BLOCK)
Block(-1,1,-1,PURPUR_BLOCK)
Block(-1,1,0,PURPUR_BLOCK)
Block(-1,1,1,PURPUR_BLOCK)
Block(-1,1,2,PURPUR_BLOCK)
Block(-1,1,3,PURPUR_BLOCK)
Block(-1,1,4,PURPUR_BLOCK)
Block(-1,1,5,PURPUR_BLOCK)
Block(-1,1,6,PURPUR_BLOCK)
Block(-1,1,7,PURPUR_BLOCK)
Block(-1,1,8,PURPUR_BLOCK)
Block(-1,1,9,PURPUR_BLOCK)
Block(-1,1,10,PURPUR_BLOCK)
Block(-1,2,-6,PURPUR_BLOCK)
Block(-1,2,-5,PURPUR_BLOCK)
Block(-1,2,-4,PURPUR_BLOCK)
Block(-1,2,-3,PURPUR_BLOCK)
Block(-1,2,-2,OBSIDIAN)
Block(-1,2,-1,OBSIDIAN)
Block(-1,2,0,OBSIDIAN)
Block(-1,2,1,OBSIDIAN)
Block(-1,2,2,OBSIDIAN)
Block(-1,2,3,OBSIDIAN)
Block(-1,2,4,OBSIDIAN)
Block(-1,2,5,OBSIDIAN)
Block(-1,2,6,OBSIDIAN)
Block(-1,2,7,OBSIDIAN)
Block(-1,2,8,OBSIDIAN)
Block(-1,2,9,OBSIDIAN)
Block(-1,2,10,OBSIDIAN)
Block(-1,2,11,PURPUR_BLOCK)
Block(-1,3,-7,PURPUR_BLOCK)
Block(-1,3,-6,PURPUR_BLOCK)
Block(-1,3,11,PURPUR_BLOCK)
Block(-1,4,-8,PURPUR_BLOCK)
Block(-1,4,11,PURPUR_BLOCK)
Block(-1,5,-8,PURPUR_BLOCK)
Block(-1,5,6,PURPUR_BLOCK)
Block(-1,5,7,PURPUR_BLOCK)
Block(-1,5,8,PURPUR_BLOCK)
Block(-1,5,9,PURPUR_BLOCK)
Block(-1,5,10,PURPUR_BLOCK)
Block(-1,5,11,PURPUR_BLOCK)
Block(-1,5,12,PURPUR_BLOCK)
Block(-1,5,13,PURPUR_STAIRS:7)
Block(-1,6,-8,PURPUR_BLOCK)
Block(-1,6,5,PURPUR_BLOCK)
Block(-1,6,6,PURPUR_STAIRS)
Block(-1,6,12,END_BRICKS)
Block(-1,7,-9,PURPUR_BLOCK)
Block(-1,7,-8,PURPUR_BLOCK)
Block(-1,7,-7,PURPUR_BLOCK)
Block(-1,7,-6,PURPUR_BLOCK)
Block(-1,7,-5,PURPUR_BLOCK)
Block(-1,7,-4,PURPUR_BLOCK)
Block(-1,7,-3,PURPUR_BLOCK)
Block(-1,7,-2,PURPUR_BLOCK)
Block(-1,7,-1,PURPUR_BLOCK)
Block(-1,7,0,PURPUR_BLOCK)
Block(-1,7,1,PURPUR_BLOCK)
Block(-1,7,2,PURPUR_BLOCK)
Block(-1,7,3,PURPUR_BLOCK)
Block(-1,7,4,PURPUR_BLOCK)
Block(-1,7,5,PURPUR_STAIRS)
Block(-1,7,12,END_BRICKS)
Block(-1,8,-9,PURPUR_BLOCK)
Block(-1,8,12,END_BRICKS)
Block(-1,9,7,PURPUR_BLOCK)
Block(-1,9,8,PURPUR_BLOCK)
Block(-1,9,9,PURPUR_BLOCK)
Block(-1,9,10,PURPUR_BLOCK)
Block(-1,9,11,PURPUR_BLOCK)
Block(-1,9,12,PURPUR_BLOCK)
Block(-1,9,13,PURPUR_BLOCK)
Block(-1,9,14,PURPUR_STAIRS:7)
Block(-1,10,7,PURPUR_STAIRS:2)
Block(-1,10,12,PURPUR_STAIRS:2)
Block(-1,10,13,PURPUR_STAIRS)
Block(-1,20,-1,PURPUR_SLAB:8)
Block(-1,20,0,PURPUR_SLAB:8)
Block(-1,20,1,PURPUR_SLAB:8)
Block(-1,21,-2,PURPUR_STAIRS:6)
Block(-1,21,2,PURPUR_STAIRS:7)
Block(0,0,-3,PURPUR_PILLAR:8)
Block(0,0,-2,PURPUR_PILLAR:8)
Block(0,0,-1,PURPUR_PILLAR:8)
Block(0,0,0,PURPUR_PILLAR:8)
Block(0,0,1,PURPUR_PILLAR:8)
Block(0,0,2,PURPUR_PILLAR:8)
Block(0,0,3,PURPUR_PILLAR:8)
Block(0,0,4,PURPUR_PILLAR:8)
Block(0,0,5,PURPUR_PILLAR:8)
Block(0,0,6,PURPUR_PILLAR:8)
Block(0,0,7,PURPUR_PILLAR:8)
Block(0,0,8,PURPUR_PILLAR:8)
Block(0,0,9,PURPUR_PILLAR:8)
Block(0,1,-6,PURPUR_PILLAR:8)
Block(0,1,-5,PURPUR_PILLAR:8)
Block(0,1,-4,PURPUR_PILLAR:8)
Block(0,1,-3,PURPUR_PILLAR:8)
Block(0,1,-2,PURPUR_BLOCK)
Block(0,1,-1,PURPUR_BLOCK)
Block(0,1,0,PURPUR_BLOCK)
Block(0,1,1,PURPUR_BLOCK)
Block(0,1,2,PURPUR_BLOCK)
Block(0,1,3,PURPUR_BLOCK)
Block(0,1,4,PURPUR_BLOCK)
Block(0,1,5,PURPUR_BLOCK)
Block(0,1,6,PURPUR_BLOCK)
Block(0,1,7,PURPUR_BLOCK)
Block(0,1,8,PURPUR_BLOCK)
Block(0,1,9,PURPUR_PILLAR:8)
Block(0,1,10,PURPUR_PILLAR:8)
Block(0,2,-8,PURPUR_PILLAR:8)
Block(0,2,-7,PURPUR_PILLAR:8)
Block(0,2,-6,PURPUR_PILLAR:8)
Block(0,2,-5,PURPUR_PILLAR:8)
Block(0,2,-4,PURPUR_PILLAR:8)
Block(0,2,-3,PURPUR_PILLAR:8)
Block(0,2,-2,PURPUR_PILLAR:8)
Block(0,2,-1,PURPUR_PILLAR:8)
Block(0,2,0,PURPUR_PILLAR:0)
Block(0,2,1,PURPUR_PILLAR:8)
Block(0,2,2,PURPUR_PILLAR:8)
Block(0,2,3,PURPUR_PILLAR:8)
Block(0,2,4,PURPUR_PILLAR:8)
Block(0,2,5,PURPUR_PILLAR:8)
Block(0,2,6,PURPUR_PILLAR:8)
Block(0,2,7,PURPUR_PILLAR:8)
Block(0,2,8,PURPUR_PILLAR:8)
Block(0,2,9,PURPUR_PILLAR:8)
Block(0,2,10,PURPUR_PILLAR:8)
Block(0,2,11,PURPUR_PILLAR:8)
Block(0,3,-9,PURPUR_PILLAR:8)
Block(0,3,-8,PURPUR_PILLAR:8)
Block(0,3,-7,PURPUR_BLOCK)
Block(0,3,-6,PURPUR_BLOCK)
Block(0,3,0,PURPUR_PILLAR:0)
Block(0,3,11,PURPUR_BLOCK)
Block(0,4,-9,PURPUR_BLOCK)
Block(0,4,-8,PURPUR_BLOCK)
Block(0,4,0,PURPUR_PILLAR:0)
Block(0,4,11,PURPUR_BLOCK)
Block(0,4,12,PURPUR_STAIRS:7)
Block(0,5,-10,PURPUR_PILLAR:8)
Block(0,5,-9,PURPUR_PILLAR:8)
Block(0,5,-8,PURPUR_BLOCK)
Block(0,5,0,PURPUR_PILLAR:0)
Block(0,5,6,PURPUR_BLOCK)
Block(0,5,7,PURPUR_BLOCK)
Block(0,5,8,PURPUR_BLOCK)
Block(0,5,9,PURPUR_BLOCK)
Block(0,5,10,PURPUR_BLOCK)
Block(0,5,11,PURPUR_BLOCK)
Block(0,5,12,PURPUR_BLOCK)
Block(0,5,13,PURPUR_STAIRS)
Block(0,6,-11,PURPUR_PILLAR:8)
Block(0,6,-10,PURPUR_PILLAR:8)
Block(0,6,-9,PURPUR_BLOCK)
Block(0,6,-8,END_ROD:3)
Block(0,6,0,PURPUR_PILLAR:0)
Block(0,6,5,PURPUR_BLOCK)
Block(0,6,6,PURPUR_BLOCK)
Block(0,6,7,PURPUR_BLOCK)
Block(0,6,11,PURPUR_PILLAR:0)
Block(0,6,12,PURPUR_PILLAR:0)
Block(0,7,-13,PURPUR_PILLAR:8)
Block(0,7,-12,PURPUR_PILLAR:8)
Block(0,7,-11,PURPUR_PILLAR:8)
Block(0,7,-10,PURPUR_PILLAR:8)
Block(0,7,-9,PURPUR_BLOCK)
Block(0,7,-8,PURPUR_BLOCK)
Block(0,7,-7,PURPUR_BLOCK)
Block(0,7,-6,PURPUR_BLOCK)
Block(0,7,-5,PURPUR_BLOCK)
Block(0,7,-4,PURPUR_BLOCK)
Block(0,7,-3,PURPUR_BLOCK)
Block(0,7,-2,PURPUR_PILLAR:8)
Block(0,7,-1,STAINED_GLASS:2)
Block(0,7,0,PURPUR_PILLAR:0)
Block(0,7,1,PURPUR_BLOCK)
Block(0,7,2,PURPUR_BLOCK)
Block(0,7,3,PURPUR_BLOCK)
Block(0,7,4,PURPUR_BLOCK)
Block(0,7,5,PURPUR_BLOCK)
Block(0,7,6,PURPUR_BLOCK)
Block(0,7,7,PURPUR_BLOCK)
Block(0,7,12,PURPUR_PILLAR:0)
Block(0,8,-13,PURPUR_STAIRS)
Block(0,8,-10,PURPUR_BLOCK)
Block(0,8,-4,PURPUR_PILLAR:8)
Block(0,8,-3,PURPUR_PILLAR:8)
Block(0,8,-2,PURPUR_STAIRS)
Block(0,8,0,PURPUR_PILLAR:0)
Block(0,8,1,LADDER:3)
Block(0,8,7,PURPUR_BLOCK)
Block(0,8,12,PURPUR_PILLAR:0)
Block(0,9,-10,END_ROD)
Block(0,9,-6,PURPUR_PILLAR:8)
Block(0,9,-5,PURPUR_PILLAR:8)
Block(0,9,-4,PURPUR_STAIRS)
Block(0,9,0,PURPUR_PILLAR:0)
Block(0,9,1,LADDER:3)
Block(0,9,6,PURPUR_BLOCK)
Block(0,9,7,PURPUR_BLOCK)
Block(0,9,8,PURPUR_BLOCK)
Block(0,9,9,PURPUR_BLOCK)
Block(0,9,10,PURPUR_BLOCK)
Block(0,9,11,PURPUR_BLOCK)
Block(0,9,12,PURPUR_BLOCK)
Block(0,9,13,PURPUR_BLOCK)
Block(0,9,14,PURPUR_STAIRS)
Block(0,10,-8,PURPUR_PILLAR:8)
Block(0,10,-7,PURPUR_PILLAR:8)
Block(0,10,-6,PURPUR_STAIRS)
Block(0,10,0,PURPUR_PILLAR:0)
Block(0,10,1,LADDER:3)
Block(0,10,6,PURPUR_BLOCK)
Block(0,10,7,PURPUR_STAIRS:0)
Block(0,10,12,PURPUR_STAIRS:2)
Block(0,10,13,PURPUR_STAIRS)
Block(0,11,-10,PURPUR_PILLAR:8)
Block(0,11,-9,PURPUR_PILLAR:8)
Block(0,11,-8,PURPUR_STAIRS)
Block(0,11,0,PURPUR_PILLAR:0)
Block(0,11,1,LADDER:3)
Block(0,12,-13,PURPUR_SLAB:8)
Block(0,12,-12,PURPUR_PILLAR:8)
Block(0,12,-11,PURPUR_PILLAR:8)
Block(0,12,-10,PURPUR_STAIRS)
Block(0,12,0,PURPUR_PILLAR:0)
Block(0,12,1,LADDER:3)
Block(0,13,0,PURPUR_PILLAR:0)
Block(0,13,1,LADDER:3)
Block(0,14,0,PURPUR_PILLAR:0)
Block(0,14,1,LADDER:3)
Block(0,15,0,PURPUR_PILLAR:0)
Block(0,15,1,LADDER:3)
Block(0,16,0,PURPUR_PILLAR:0)
Block(0,16,1,LADDER:3)
Block(0,17,0,PURPUR_PILLAR:0)
Block(0,17,1,LADDER:3)
Block(0,18,0,PURPUR_PILLAR:0)
Block(0,18,1,LADDER:3)
Block(0,19,0,PURPUR_PILLAR:0)
Block(0,19,1,LADDER:3)
Block(0,20,0,PURPUR_PILLAR:0)
Block(0,20,1,LADDER:3)
Block(0,21,-2,PURPUR_STAIRS:6)
Block(0,21,0,PURPUR_PILLAR:0)
Block(0,21,1,LADDER:3)
Block(0,21,2,PURPUR_STAIRS:7)
Block(0,22,0,PURPUR_PILLAR:0)
Block(0,23,0,PURPUR_BLOCK)
Block(1,1,-2,PURPUR_BLOCK)
Block(1,1,-1,PURPUR_BLOCK)
Block(1,1,0,PURPUR_BLOCK)
Block(1,1,1,PURPUR_BLOCK)
Block(1,1,2,PURPUR_BLOCK)
Block(1,1,3,PURPUR_BLOCK)
Block(1,1,4,PURPUR_BLOCK)
Block(1,1,5,PURPUR_BLOCK)
Block(1,1,6,PURPUR_BLOCK)
Block(1,1,7,PURPUR_BLOCK)
Block(1,1,8,PURPUR_BLOCK)
Block(1,1,9,PURPUR_BLOCK)
Block(1,1,10,PURPUR_BLOCK)
Block(1,2,-6,PURPUR_BLOCK)
Block(1,2,-5,PURPUR_BLOCK)
Block(1,2,-4,PURPUR_BLOCK)
Block(1,2,-3,PURPUR_BLOCK)
Block(1,2,-2,OBSIDIAN)
Block(1,2,-1,OBSIDIAN)
Block(1,2,0,OBSIDIAN)
Block(1,2,1,OBSIDIAN)
Block(1,2,2,OBSIDIAN)
Block(1,2,3,OBSIDIAN)
Block(1,2,4,OBSIDIAN)
Block(1,2,5,OBSIDIAN)
Block(1,2,6,OBSIDIAN)
Block(1,2,7,OBSIDIAN)
Block(1,2,8,OBSIDIAN)
Block(1,2,9,OBSIDIAN)
Block(1,2,10,OBSIDIAN)
Block(1,2,11,PURPUR_BLOCK)
Block(1,3,-7,PURPUR_BLOCK)
Block(1,3,-6,PURPUR_BLOCK)
Block(1,3,11,PURPUR_BLOCK)
Block(1,4,-8,PURPUR_BLOCK)
Block(1,4,11,PURPUR_BLOCK)
Block(1,5,-8,PURPUR_BLOCK)
Block(1,5,6,PURPUR_BLOCK)
Block(1,5,7,PURPUR_BLOCK)
Block(1,5,8,PURPUR_BLOCK)
Block(1,5,9,PURPUR_BLOCK)
Block(1,5,10,PURPUR_BLOCK)
Block(1,5,11,PURPUR_BLOCK)
Block(1,5,12,PURPUR_BLOCK)
Block(1,5,13,PURPUR_STAIRS:7)
Block(1,6,-8,PURPUR_BLOCK)
Block(1,6,5,PURPUR_BLOCK)
Block(1,6,6,PURPUR_BLOCK)
Block(1,6,7,PURPUR_BLOCK)
Block(1,6,12,END_BRICKS)
Block(1,7,-9,PURPUR_BLOCK)
Block(1,7,-8,PURPUR_BLOCK)
Block(1,7,-7,PURPUR_BLOCK)
Block(1,7,-6,PURPUR_BLOCK)
Block(1,7,-5,PURPUR_BLOCK)
Block(1,7,-4,PURPUR_BLOCK)
Block(1,7,-3,PURPUR_BLOCK)
Block(1,7,-2,PURPUR_BLOCK)
Block(1,7,-1,PURPUR_BLOCK)
Block(1,7,0,PURPUR_BLOCK)
Block(1,7,1,PURPUR_BLOCK)
Block(1,7,2,PURPUR_BLOCK)
Block(1,7,3,PURPUR_BLOCK)
Block(1,7,4,PURPUR_BLOCK)
Block(1,7,5,PURPUR_BLOCK)
Block(1,7,6,PURPUR_BLOCK)
Block(1,7,7,PURPUR_BLOCK)
Block(1,7,12,END_BRICKS)
Block(1,8,-9,PURPUR_BLOCK)
Block(1,8,7,PURPUR_BLOCK)
Block(1,8,12,END_BRICKS)
Block(1,9,6,PURPUR_BLOCK)
Block(1,9,7,PURPUR_BLOCK)
Block(1,9,8,PURPUR_BLOCK)
Block(1,9,9,PURPUR_BLOCK)
Block(1,9,10,PURPUR_BLOCK)
Block(1,9,11,PURPUR_BLOCK)
Block(1,9,12,PURPUR_BLOCK)
Block(1,9,13,PURPUR_BLOCK)
Block(1,9,14,PURPUR_STAIRS:7)
Block(1,10,6,PURPUR_BLOCK)
Block(1,10,12,PURPUR_STAIRS:2)
Block(1,10,13,PURPUR_STAIRS)
Block(1,20,-1,PURPUR_SLAB:8)
Block(1,20,0,PURPUR_SLAB:8)
Block(1,20,1,PURPUR_SLAB:8)
Block(1,21,-2,PURPUR_STAIRS:6)
Block(1,21,2,PURPUR_STAIRS:7)
Block(2,1,-1,PURPUR_STAIRS:5)
Block(2,1,3,PURPUR_STAIRS:5)
Block(2,1,7,PURPUR_STAIRS:5)
Block(2,2,-4,PURPUR_BLOCK)
Block(2,2,-3,PURPUR_BLOCK)
Block(2,2,-2,PURPUR_BLOCK)
Block(2,2,-1,PURPUR_BLOCK)
Block(2,2,0,PURPUR_BLOCK)
Block(2,2,1,PURPUR_BLOCK)
Block(2,2,2,PURPUR_BLOCK)
Block(2,2,3,PURPUR_BLOCK)
Block(2,2,4,PURPUR_BLOCK)
Block(2,2,5,PURPUR_BLOCK)
Block(2,2,6,PURPUR_BLOCK)
Block(2,2,7,PURPUR_BLOCK)
Block(2,2,8,PURPUR_BLOCK)
Block(2,2,9,PURPUR_BLOCK)
Block(2,2,10,PURPUR_BLOCK)
Block(2,2,11,PURPUR_BLOCK)
Block(2,3,-6,PURPUR_BLOCK)
Block(2,3,-5,PURPUR_BLOCK)
Block(2,3,1,PURPUR_STAIRS:2)
Block(2,3,2,PURPUR_BLOCK)
Block(2,3,3,PURPUR_BLOCK)
Block(2,3,4,PURPUR_BLOCK)
Block(2,3,5,PURPUR_BLOCK)
Block(2,3,6,PURPUR_BLOCK)
Block(2,3,7,PURPUR_BLOCK)
Block(2,3,8,PURPUR_BLOCK)
Block(2,3,9,PURPUR_BLOCK)
Block(2,3,10,PURPUR_BLOCK)
Block(2,3,11,PURPUR_BLOCK)
Block(2,4,-7,PURPUR_BLOCK)
Block(2,4,-6,PURPUR_BLOCK)
Block(2,4,5,PURPUR_STAIRS:2)
Block(2,4,6,PURPUR_BLOCK)
Block(2,4,7,PURPUR_BLOCK)
Block(2,4,8,PURPUR_BLOCK)
Block(2,4,9,PURPUR_BLOCK)
Block(2,4,10,PURPUR_BLOCK)
Block(2,4,11,PURPUR_BLOCK)
Block(2,5,-7,PURPUR_BLOCK)
Block(2,5,-6,PURPUR_BLOCK)
Block(2,5,6,PURPUR_STAIRS:2)
Block(2,5,7,PURPUR_BLOCK)
Block(2,5,8,PURPUR_BLOCK)
Block(2,5,9,PURPUR_BLOCK)
Block(2,5,10,PURPUR_BLOCK)
Block(2,5,11,PURPUR_BLOCK)
Block(2,5,12,PURPUR_BLOCK)
Block(2,5,13,PURPUR_STAIRS:7)
Block(2,6,-7,PURPUR_BLOCK)
Block(2,6,-6,PURPUR_BLOCK)
Block(2,6,12,END_BRICKS)
Block(2,7,-8,PURPUR_BLOCK)
Block(2,7,-7,PURPUR_BLOCK)
Block(2,7,-6,PURPUR_BLOCK)
Block(2,7,-5,PURPUR_BLOCK)
Block(2,7,-4,PURPUR_BLOCK)
Block(2,7,-3,PURPUR_BLOCK)
Block(2,7,-2,PURPUR_BLOCK)
Block(2,7,-1,PURPUR_BLOCK)
Block(2,7,0,PURPUR_BLOCK)
Block(2,7,1,PURPUR_BLOCK)
Block(2,7,2,PURPUR_BLOCK)
Block(2,7,3,PURPUR_BLOCK)
Block(2,7,4,PURPUR_BLOCK)
Block(2,7,12,STAINED_GLASS:2)
Block(2,8,-8,PURPUR_BLOCK)
Block(2,8,-7,PURPUR_STAIRS:1)
Block(2,8,-6,PURPUR_STAIRS:2)
Block(2,8,5,PURPUR_STAIRS:2)
Block(2,8,6,PURPUR_BLOCK)
Block(2,8,7,PURPUR_STAIRS:7)
Block(2,8,12,END_BRICKS)
Block(2,9,6,PURPUR_STAIRS:2)
Block(2,9,7,PURPUR_BLOCK)
Block(2,9,8,PURPUR_BLOCK)
Block(2,9,9,PURPUR_BLOCK)
Block(2,9,10,PURPUR_BLOCK)
Block(2,9,11,PURPUR_BLOCK)
Block(2,9,12,PURPUR_BLOCK)
Block(2,9,13,PURPUR_BLOCK)
Block(2,9,14,PURPUR_STAIRS:7)
Block(2,10,12,PURPUR_STAIRS:1)
Block(2,10,13,PURPUR_BLOCK)
Block(2,21,-2,PURPUR_STAIRS:5)
Block(2,21,-1,PURPUR_STAIRS:5)
Block(2,21,0,PURPUR_STAIRS:5)
Block(2,21,1,PURPUR_STAIRS:5)
Block(2,21,2,PURPUR_STAIRS:7)
Block(3,2,-1,PURPUR_STAIRS:5)
Block(3,2,3,PURPUR_STAIRS:5)
Block(3,2,7,PURPUR_STAIRS:5)
Block(3,2,11,PURPUR_STAIRS:5)
Block(3,3,-4,PURPUR_BLOCK)
Block(3,3,-3,PURPUR_BLOCK)
Block(3,3,-2,PURPUR_BLOCK)
Block(3,3,-1,PURPUR_BLOCK)
Block(3,3,0,PURPUR_BLOCK)
Block(3,3,1,PURPUR_BLOCK)
Block(3,3,2,PURPUR_BLOCK)
Block(3,3,3,PURPUR_BLOCK)
Block(3,3,4,PURPUR_BLOCK)
Block(3,3,5,PURPUR_BLOCK)
Block(3,3,6,PURPUR_BLOCK)
Block(3,3,7,PURPUR_BLOCK)
Block(3,3,8,PURPUR_BLOCK)
Block(3,3,9,PURPUR_BLOCK)
Block(3,3,10,PURPUR_BLOCK)
Block(3,3,11,PURPUR_BLOCK)
Block(3,4,-5,PURPUR_BLOCK)
Block(3,4,-4,PURPUR_BLOCK)
Block(3,4,5,PURPUR_STAIRS:2)
Block(3,4,6,PURPUR_BLOCK)
Block(3,4,7,PURPUR_BLOCK)
Block(3,4,8,PURPUR_BLOCK)
Block(3,4,9,PURPUR_BLOCK)
Block(3,4,10,PURPUR_BLOCK)
Block(3,4,11,PURPUR_BLOCK)
Block(3,5,-5,PURPUR_BLOCK)
Block(3,5,-4,PURPUR_BLOCK)
Block(3,5,6,PURPUR_STAIRS:2)
Block(3,5,7,PURPUR_BLOCK)
Block(3,5,8,PURPUR_BLOCK)
Block(3,5,9,PURPUR_BLOCK)
Block(3,5,10,PURPUR_BLOCK)
Block(3,5,11,PURPUR_BLOCK)
Block(3,5,12,PURPUR_BLOCK)
Block(3,5,13,PURPUR_STAIRS:7)
Block(3,6,-5,PURPUR_BLOCK)
Block(3,6,-4,PURPUR_BLOCK)
Block(3,6,12,END_BRICKS)
Block(3,7,-6,PURPUR_BLOCK)
Block(3,7,-5,PURPUR_BLOCK)
Block(3,7,-4,PURPUR_BLOCK)
Block(3,7,-3,PURPUR_BLOCK)
Block(3,7,-2,PURPUR_BLOCK)
Block(3,7,-1,PURPUR_BLOCK)
Block(3,7,0,PURPUR_BLOCK)
Block(3,7,1,PURPUR_BLOCK)
Block(3,7,2,PURPUR_BLOCK)
Block(3,7,3,PURPUR_BLOCK)
Block(3,7,4,PURPUR_BLOCK)
Block(3,7,12,END_BRICKS)
Block(3,8,-6,PURPUR_BLOCK)
Block(3,8,-5,PURPUR_STAIRS:1)
Block(3,8,-4,PURPUR_STAIRS:2)
Block(3,8,5,PURPUR_STAIRS:2)
Block(3,8,6,PURPUR_BLOCK)
Block(3,8,7,PURPUR_STAIRS:7)
Block(3,8,12,END_BRICKS)
Block(3,9,6,PURPUR_STAIRS:2)
Block(3,9,7,PURPUR_BLOCK)
Block(3,9,8,PURPUR_BLOCK)
Block(3,9,9,PURPUR_BLOCK)
Block(3,9,10,PURPUR_BLOCK)
Block(3,9,11,PURPUR_BLOCK)
Block(3,9,12,PURPUR_BLOCK)
Block(3,9,13,PURPUR_BLOCK)
Block(3,9,14,PURPUR_STAIRS)
Block(3,10,13,PURPUR_STAIRS)
Block(4,3,-1,PURPUR_STAIRS:5)
Block(4,3,3,PURPUR_STAIRS:5)
Block(4,3,7,PURPUR_STAIRS:5)
Block(4,3,11,PURPUR_STAIRS:5)
Block(4,4,-3,PURPUR_BLOCK)
Block(4,4,-2,PURPUR_BLOCK)
Block(4,4,-1,PURPUR_BLOCK)
Block(4,4,0,PURPUR_BLOCK)
Block(4,4,1,PURPUR_BLOCK)
Block(4,4,2,PURPUR_BLOCK)
Block(4,4,3,PURPUR_BLOCK)
Block(4,4,4,PURPUR_BLOCK)
Block(4,4,5,PURPUR_BLOCK)
Block(4,4,6,PURPUR_BLOCK)
Block(4,4,7,PURPUR_BLOCK)
Block(4,4,8,PURPUR_BLOCK)
Block(4,4,9,PURPUR_BLOCK)
Block(4,4,10,PURPUR_BLOCK)
Block(4,4,11,PURPUR_BLOCK)
Block(4,4,12,PURPUR_STAIRS:7)
Block(4,5,-3,PURPUR_BLOCK)
Block(4,5,-2,PURPUR_BLOCK)
Block(4,5,-1,PURPUR_BLOCK)
Block(4,5,0,PURPUR_BLOCK)
Block(4,5,1,PURPUR_BLOCK)
Block(4,5,2,PURPUR_BLOCK)
Block(4,5,3,PURPUR_BLOCK)
Block(4,5,4,PURPUR_BLOCK)
Block(4,5,5,PURPUR_BLOCK)
Block(4,5,6,PURPUR_BLOCK)
Block(4,5,7,PURPUR_BLOCK)
Block(4,5,8,PURPUR_BLOCK)
Block(4,5,9,PURPUR_BLOCK)
Block(4,5,10,PURPUR_BLOCK)
Block(4,5,11,PURPUR_BLOCK)
Block(4,5,12,PURPUR_BLOCK)
Block(4,5,13,PURPUR_STAIRS:7)
Block(4,6,-3,PURPUR_BLOCK)
Block(4,6,-2,PURPUR_BLOCK)
Block(4,6,0,PURPUR_BLOCK)
Block(4,6,1,PURPUR_BLOCK)
Block(4,6,3,PURPUR_BLOCK)
Block(4,6,4,PURPUR_BLOCK)
Block(4,6,5,PURPUR_BLOCK)
Block(4,6,6,PURPUR_BLOCK)
Block(4,6,7,PURPUR_PILLAR:0)
Block(4,6,8,END_BRICKS)
Block(4,6,9,END_BRICKS)
Block(4,6,10,END_BRICKS)
Block(4,6,11,END_BRICKS)
Block(4,6,12,PURPUR_PILLAR:0)
Block(4,7,-4,PURPUR_BLOCK)
Block(4,7,-3,PURPUR_BLOCK)
Block(4,7,-2,PURPUR_BLOCK)
Block(4,7,-1,PURPUR_BLOCK)
Block(4,7,0,PURPUR_BLOCK)
Block(4,7,1,PURPUR_BLOCK)
Block(4,7,2,PURPUR_BLOCK)
Block(4,7,3,PURPUR_BLOCK)
Block(4,7,4,PURPUR_BLOCK)
Block(4,7,5,PURPUR_BLOCK)
Block(4,7,6,PURPUR_BLOCK)
Block(4,7,7,PURPUR_PILLAR:0)
Block(4,7,8,END_BRICKS)
Block(4,7,9,STAINED_GLASS:2)
Block(4,7,10,STAINED_GLASS:2)
Block(4,7,11,END_BRICKS)
Block(4,7,12,PURPUR_PILLAR:0)
Block(4,8,-4,PURPUR_BLOCK)
Block(4,8,-3,PURPUR_STAIRS:1)
Block(4,8,-2,PURPUR_STAIRS:1)
Block(4,8,-1,PURPUR_BLOCK)
Block(4,8,0,PURPUR_STAIRS:1)
Block(4,8,1,PURPUR_STAIRS:1)
Block(4,8,2,PURPUR_BLOCK)
Block(4,8,3,PURPUR_STAIRS:1)
Block(4,8,4,PURPUR_STAIRS:1)
Block(4,8,5,PURPUR_BLOCK)
Block(4,8,6,PURPUR_BLOCK)
Block(4,8,7,PURPUR_PILLAR:0)
Block(4,8,8,END_BRICKS)
Block(4,8,9,END_BRICKS)
Block(4,8,10,END_BRICKS)
Block(4,8,11,END_BRICKS)
Block(4,8,12,PURPUR_PILLAR:0)
Block(4,9,-4,END_ROD)
Block(4,9,6,PURPUR_BLOCK)
Block(4,9,7,PURPUR_BLOCK)
Block(4,9,8,PURPUR_BLOCK)
Block(4,9,9,PURPUR_BLOCK)
Block(4,9,10,PURPUR_BLOCK)
Block(4,9,11,PURPUR_BLOCK)
Block(4,9,12,PURPUR_BLOCK)
Block(4,9,13,PURPUR_BLOCK)
Block(4,9,14,PURPUR_STAIRS)
Block(4,10,6,PURPUR_BLOCK)
Block(4,10,13,PURPUR_STAIRS)
Block(5,5,-1,PURPUR_STAIRS:5)
Block(5,5,2,PURPUR_STAIRS:5)
Block(5,5,6,PURPUR_STAIRS:6)
Block(5,5,7,PURPUR_STAIRS:5)
Block(5,5,8,PURPUR_STAIRS:1)
Block(5,5,9,PURPUR_STAIRS:5)
Block(5,5,10,PURPUR_STAIRS:5)
Block(5,5,11,PURPUR_STAIRS:1)
Block(5,5,12,PURPUR_STAIRS:5)
Block(5,5,13,PURPUR_STAIRS:7)
Block(5,6,13,END_ROD)
Block(5,9,5,PURPUR_STAIRS:6)
Block(5,9,6,PURPUR_BLOCK)
Block(5,9,7,PURPUR_BLOCK)
Block(5,9,8,PURPUR_BLOCK)
Block(5,9,9,PURPUR_BLOCK)
Block(5,9,10,PURPUR_BLOCK)
Block(5,9,11,PURPUR_BLOCK)
Block(5,9,12,PURPUR_BLOCK)
Block(5,9,13,PURPUR_BLOCK)
Block(5,9,14,PURPUR_STAIRS:7)
Block(5,10,6,PURPUR_BLOCK)
Block(5,10,7,PURPUR_STAIRS:1)
Block(5,10,8,PURPUR_STAIRS:1)
Block(5,10,9,PURPUR_STAIRS:1)
Block(5,10,10,PURPUR_STAIRS:1)
Block(5,10,11,PURPUR_STAIRS:1)
Block(5,10,12,PURPUR_STAIRS:1)
Block(5,10,13,PURPUR_BLOCK)
Block(6,9,5,PURPUR_STAIRS:6)
Block(6,9,6,PURPUR_STAIRS:5)
Block(6,9,7,PURPUR_STAIRS:1)
Block(6,9,8,PURPUR_STAIRS:1)
Block(6,9,9,PURPUR_STAIRS:5)
Block(6,9,10,PURPUR_STAIRS:5)
Block(6,9,11,PURPUR_STAIRS:1)
Block(6,9,12,PURPUR_STAIRS:1)
Block(6,9,13,PURPUR_STAIRS:5)
Block(6,9,14,PURPUR_STAIRS:5)

#######################################################################
# +-----------------------------------------------------------------+ #
# |                            BO3 checks                           | #
# +-----------------------------------------------------------------+ #
#######################################################################


#######################################################################
# +-----------------------------------------------------------------+ #
# |                             Branches                            | #
# +-----------------------------------------------------------------+ #
#######################################################################


#######################################################################
# +-----------------------------------------------------------------+ #
# |                             Entities                            | #
# +-----------------------------------------------------------------+ #
#######################################################################


#######################################################################
# +-----------------------------------------------------------------+ #
# |                            Particles                            | #
# +-----------------------------------------------------------------+ #
#######################################################################


#######################################################################
# +-----------------------------------------------------------------+ #
# |                             Spawners                            | #
# +-----------------------------------------------------------------+ #
#######################################################################


#######################################################################
# +-----------------------------------------------------------------+ #
# |                             ModData                             | #
# +-----------------------------------------------------------------+ #
#######################################################################

